2022-12-27 21:48:29,494 INFO Secondary host has been started
2022-12-27 21:49:17,023 INFO Secondary host has been started
2022-12-27 21:49:17,023 ERROR Exception: list index out of range
Stack (most recent call last):
  File "/home/artemius/replicated-log/secondary2/./secondary.py", line 101, in <module>
    main()
  File "/home/artemius/replicated-log/secondary2/./secondary.py", line 86, in main
    logging.error(f"Exception: {e}", stack_info=debug)
2022-12-27 21:49:46,048 INFO Secondary host has been started
2022-12-27 21:51:24,953 INFO Secondary host has been started
2022-12-27 21:52:14,052 INFO Secondary host has been started
2022-12-27 21:52:14,053 INFO HTTP server started and listening on 8081
2022-12-27 21:52:21,335 INFO 127.0.0.1 requested list of messages
2022-12-27 21:52:21,336 INFO The replication log is empty

2022-12-27 21:52:24,437 INFO 127.0.0.1 requested list of messages
2022-12-27 21:52:24,438 INFO The replication log is empty

2022-12-27 22:15:06,223 INFO Secondary host has been started
2022-12-27 22:15:06,224 ERROR Exception: list index out of range
Stack (most recent call last):
  File "/home/artemius/replicated-log/secondary2/./secondary.py", line 106, in <module>
    main()
  File "/home/artemius/replicated-log/secondary2/./secondary.py", line 86, in main
    logging.error(f"Exception: {e}", stack_info=debug)
2022-12-27 22:15:14,522 INFO Secondary host has been started
2022-12-27 22:15:14,522 ERROR Exception: list index out of range
Stack (most recent call last):
  File "/home/artemius/replicated-log/secondary2/./secondary.py", line 106, in <module>
    main()
  File "/home/artemius/replicated-log/secondary2/./secondary.py", line 86, in main
    logging.error(f"Exception: {e}", stack_info=debug)
2022-12-27 22:15:15,788 INFO Secondary host has been started
2022-12-27 22:15:15,788 ERROR Exception: list index out of range
Stack (most recent call last):
  File "/home/artemius/replicated-log/secondary2/./secondary.py", line 106, in <module>
    main()
  File "/home/artemius/replicated-log/secondary2/./secondary.py", line 86, in main
    logging.error(f"Exception: {e}", stack_info=debug)
2022-12-27 22:16:15,032 INFO Secondary host has been started
2022-12-27 22:16:15,032 ERROR Exception: list index out of range
Stack (most recent call last):
  File "/home/artemius/replicated-log/secondary2/./secondary.py", line 107, in <module>
    main()
  File "/home/artemius/replicated-log/secondary2/./secondary.py", line 86, in main
    logging.error(f"Exception: {e}", stack_info=debug)
2022-12-27 22:16:58,891 INFO Secondary host has been started
2022-12-27 22:16:58,892 ERROR Exception: list index out of range
Stack (most recent call last):
  File "/home/artemius/replicated-log/secondary2/./secondary.py", line 106, in <module>
    main()
  File "/home/artemius/replicated-log/secondary2/./secondary.py", line 86, in main
    logging.error(f"Exception: {e}", stack_info=debug)
2022-12-27 22:17:25,067 INFO Secondary host has been started
2022-12-27 22:17:25,069 INFO HTTP server started and listening on 8081
2022-12-27 22:17:28,377 INFO Secondary host has been started
2022-12-27 22:17:28,378 INFO HTTP server started and listening on 8081
2022-12-27 22:18:01,876 INFO Secondary host has been started
2022-12-27 22:18:01,876 ERROR Exception: list index out of range
Stack (most recent call last):
  File "/home/artemius/replicated-log/secondary2/./secondary.py", line 107, in <module>
    main()
  File "/home/artemius/replicated-log/secondary2/./secondary.py", line 87, in main
    logging.error(f"Exception: {e}", stack_info=debug)
2022-12-27 22:22:59,630 INFO Secondary host has been started
2022-12-27 22:22:59,630 ERROR Exception: list index out of range
Stack (most recent call last):
  File "/home/artemius/replicated-log/secondary2/./secondary.py", line 107, in <module>
    main()
  File "/home/artemius/replicated-log/secondary2/./secondary.py", line 86, in main
    logging.error(f"Exception: {e}", stack_info=debug)
2022-12-27 22:25:07,500 INFO Secondary host has been started
2022-12-27 22:25:07,500 ERROR Exception: list index out of range
Stack (most recent call last):
  File "/home/artemius/replicated-log/secondary2/./secondary.py", line 108, in <module>
    main()
  File "/home/artemius/replicated-log/secondary2/./secondary.py", line 87, in main
    logging.error(f"Exception: {e}", stack_info=debug)
2022-12-27 22:27:56,884 INFO Secondary host has been started
2022-12-27 22:27:56,884 ERROR Exception: list index out of range
Stack (most recent call last):
  File "/home/artemius/replicated-log/secondary2/./secondary.py", line 107, in <module>
    main()
  File "/home/artemius/replicated-log/secondary2/./secondary.py", line 87, in main
    logging.error(f"Exception: {e}", stack_info=debug)
2022-12-27 22:28:07,671 INFO Secondary host has been started
2022-12-27 22:28:07,671 ERROR Exception: list index out of range
Stack (most recent call last):
  File "/home/artemius/replicated-log/secondary2/./secondary.py", line 107, in <module>
    main()
  File "/home/artemius/replicated-log/secondary2/./secondary.py", line 87, in main
    logging.error(f"Exception: {e}", stack_info=debug)
2022-12-27 22:28:56,556 INFO Secondary host has been started
2022-12-27 22:28:56,557 ERROR Exception: list index out of range
Stack (most recent call last):
  File "/home/artemius/replicated-log/secondary2/./secondary.py", line 109, in <module>
    main()
  File "/home/artemius/replicated-log/secondary2/./secondary.py", line 89, in main
    logging.error(f"Exception: {e}", stack_info=debug)
2022-12-27 22:29:11,836 INFO Secondary host has been started
2022-12-27 22:29:11,836 ERROR Exception: list index out of range
Stack (most recent call last):
  File "/home/artemius/replicated-log/secondary2/./secondary.py", line 110, in <module>
    main()
  File "/home/artemius/replicated-log/secondary2/./secondary.py", line 90, in main
    logging.error(f"Exception: {e}", stack_info=debug)
2022-12-27 22:29:28,403 INFO Secondary host has been started
2022-12-27 22:29:28,403 ERROR Exception: list index out of range
Stack (most recent call last):
  File "/home/artemius/replicated-log/secondary2/./secondary.py", line 107, in <module>
    main()
  File "/home/artemius/replicated-log/secondary2/./secondary.py", line 87, in main
    logging.error(f"Exception: {e}", stack_info=debug)
2022-12-27 22:29:51,753 INFO Secondary host has been started
2022-12-27 22:29:51,754 ERROR Exception: list index out of range
Stack (most recent call last):
  File "/home/artemius/replicated-log/secondary2/./secondary.py", line 107, in <module>
    main()
  File "/home/artemius/replicated-log/secondary2/./secondary.py", line 87, in main
    logging.error(f"Exception: {e}", stack_info=debug)
2022-12-27 22:29:59,927 INFO Secondary host has been started
2022-12-27 22:29:59,928 INFO HTTP server started and listening on 8082
2022-12-27 22:30:11,648 INFO Secondary host has been started
2022-12-27 22:30:11,650 INFO HTTP server started and listening on 8082
2022-12-27 22:30:21,393 INFO Secondary host has been started
2022-12-27 22:30:21,395 INFO HTTP server started and listening on 8082
2022-12-27 22:30:27,036 INFO Secondary host has been started
2022-12-27 22:30:27,037 INFO HTTP server started and listening on 8081
